fatal: Unable to create '/fsx-storygen/beidic/yang/GRIFFIN2/.git/index.lock': File exists.

Another git process seems to be running in this repository, e.g.
an editor opened by 'git commit'. Please make sure all processes
are terminated then try again. If it still fails, a git process
may have crashed in this repository earlier:
remove the file manually to continue.
Your configuration specifies to merge with the ref 'refs/heads/yangexp2'
from the remote, but no such ref was fetched.
wandb: Currently logged in as: stevenzhou0816100. Use `wandb login --relogin` to force relogin
The following values were not passed to `accelerate launch` and had defaults used instead:
		More than one GPU was found, enabling multi-GPU training.
		If this was unintended please pass in `--num_processes=1`.
	`--mixed_precision` was set to a value of `'no'`
	`--dynamo_backend` was set to a value of `'no'`
To avoid this warning pass in values for each of the problematic parameters or run `accelerate config`.
2024-07-24:22:48:38,510 INFO     [main.py:288] Verbosity set to INFO
2024-07-24:22:48:38,510 INFO     [main.py:288] Verbosity set to INFO
2024-07-24:22:48:38,510 INFO     [main.py:288] Verbosity set to INFO
2024-07-24:22:48:38,510 INFO     [main.py:288] Verbosity set to INFO
2024-07-24:22:48:38,511 INFO     [main.py:288] Verbosity set to INFO
2024-07-24:22:48:38,511 INFO     [main.py:288] Verbosity set to INFO
2024-07-24:22:48:38,511 INFO     [main.py:288] Verbosity set to INFO
2024-07-24:22:48:38,512 INFO     [main.py:288] Verbosity set to INFO
2024-07-24:22:48:47,656 ERROR    [main.py:344] Tasks were not found: gsm8k-cot
                                               Try `lm-eval --tasks list` for list of available tasks
2024-07-24:22:48:47,656 ERROR    [main.py:344] Tasks were not found: gsm8k-cot
                                               Try `lm-eval --tasks list` for list of available tasks
2024-07-24:22:48:47,656 ERROR    [main.py:344] Tasks were not found: gsm8k-cot
                                               Try `lm-eval --tasks list` for list of available tasks
2024-07-24:22:48:47,656 ERROR    [main.py:344] Tasks were not found: gsm8k-cot
                                               Try `lm-eval --tasks list` for list of available tasks
2024-07-24:22:48:47,656 ERROR    [main.py:344] Tasks were not found: gsm8k-cot
                                               Try `lm-eval --tasks list` for list of available tasks
2024-07-24:22:48:47,656 ERROR    [main.py:344] Tasks were not found: gsm8k-cot
                                               Try `lm-eval --tasks list` for list of available tasks
2024-07-24:22:48:47,656 ERROR    [main.py:344] Tasks were not found: gsm8k-cot
                                               Try `lm-eval --tasks list` for list of available tasks
2024-07-24:22:48:47,656 ERROR    [main.py:344] Tasks were not found: gsm8k-cot
                                               Try `lm-eval --tasks list` for list of available tasks
Traceback (most recent call last):
  File "/opt/hpcaas/.mounts/fs-03efe25c053395d1f/beidic/yang/GRIFFIN2/main.py", line 465, in <module>
Traceback (most recent call last):
Traceback (most recent call last):
  File "/opt/hpcaas/.mounts/fs-03efe25c053395d1f/beidic/yang/GRIFFIN2/main.py", line 465, in <module>
  File "/opt/hpcaas/.mounts/fs-03efe25c053395d1f/beidic/yang/GRIFFIN2/main.py", line 465, in <module>
Traceback (most recent call last):
  File "/opt/hpcaas/.mounts/fs-03efe25c053395d1f/beidic/yang/GRIFFIN2/main.py", line 465, in <module>
Traceback (most recent call last):
  File "/opt/hpcaas/.mounts/fs-03efe25c053395d1f/beidic/yang/GRIFFIN2/main.py", line 465, in <module>
Traceback (most recent call last):
Traceback (most recent call last):
  File "/opt/hpcaas/.mounts/fs-03efe25c053395d1f/beidic/yang/GRIFFIN2/main.py", line 465, in <module>
  File "/opt/hpcaas/.mounts/fs-03efe25c053395d1f/beidic/yang/GRIFFIN2/main.py", line 465, in <module>
Traceback (most recent call last):
  File "/opt/hpcaas/.mounts/fs-03efe25c053395d1f/beidic/yang/GRIFFIN2/main.py", line 465, in <module>
    cli_evaluate()
  File "/opt/hpcaas/.mounts/fs-03efe25c053395d1f/beidic/yang/GRIFFIN2/main.py", line 348, in cli_evaluate
                cli_evaluate()    cli_evaluate()    cli_evaluate()cli_evaluate()
cli_evaluate()
    cli_evaluate()

  File "/opt/hpcaas/.mounts/fs-03efe25c053395d1f/beidic/yang/GRIFFIN2/main.py", line 348, in cli_evaluate

  File "/opt/hpcaas/.mounts/fs-03efe25c053395d1f/beidic/yang/GRIFFIN2/main.py", line 348, in cli_evaluate
raise ValueError(
  File "/opt/hpcaas/.mounts/fs-03efe25c053395d1f/beidic/yang/GRIFFIN2/main.py", line 348, in cli_evaluate
  File "/opt/hpcaas/.mounts/fs-03efe25c053395d1f/beidic/yang/GRIFFIN2/main.py", line 348, in cli_evaluate
  File "/opt/hpcaas/.mounts/fs-03efe25c053395d1f/beidic/yang/GRIFFIN2/main.py", line 348, in cli_evaluate

  File "/opt/hpcaas/.mounts/fs-03efe25c053395d1f/beidic/yang/GRIFFIN2/main.py", line 348, in cli_evaluate
ValueError: Tasks not found: gsm8k-cot. Try `lm-eval --tasks list` for list of available tasks, or '--verbosity DEBUG' to troubleshoot task registration issues.
    cli_evaluate()
  File "/opt/hpcaas/.mounts/fs-03efe25c053395d1f/beidic/yang/GRIFFIN2/main.py", line 348, in cli_evaluate
    raise ValueError(
ValueError: Tasks not found: gsm8k-cot. Try `lm-eval --tasks list` for list of available tasks, or '--verbosity DEBUG' to troubleshoot task registration issues.
            raise ValueError(        raise ValueError(raise ValueError(
raise ValueError(raise ValueError(


ValueError
ValueErrorValueError: ValueError: ValueError: Tasks not found: gsm8k-cot. Try `lm-eval --tasks list` for list of available tasks, or '--verbosity DEBUG' to troubleshoot task registration issues.: Tasks not found: gsm8k-cot. Try `lm-eval --tasks list` for list of available tasks, or '--verbosity DEBUG' to troubleshoot task registration issues.: Tasks not found: gsm8k-cot. Try `lm-eval --tasks list` for list of available tasks, or '--verbosity DEBUG' to troubleshoot task registration issues.
Tasks not found: gsm8k-cot. Try `lm-eval --tasks list` for list of available tasks, or '--verbosity DEBUG' to troubleshoot task registration issues.
Tasks not found: gsm8k-cot. Try `lm-eval --tasks list` for list of available tasks, or '--verbosity DEBUG' to troubleshoot task registration issues.


    raise ValueError(
ValueError: Tasks not found: gsm8k-cot. Try `lm-eval --tasks list` for list of available tasks, or '--verbosity DEBUG' to troubleshoot task registration issues.
[2024-07-24 22:48:50,553] torch.distributed.elastic.multiprocessing.api: [ERROR] failed (exitcode: 1) local_rank: 0 (pid: 3831142) of binary: /fsx-storygen/beidic/anaconda3/envs/griffin/bin/python3.9
Traceback (most recent call last):
  File "/fsx-storygen/beidic/anaconda3/envs/griffin/bin/accelerate", line 8, in <module>
    sys.exit(main())
  File "/fsx-storygen/beidic/anaconda3/envs/griffin/lib/python3.9/site-packages/accelerate/commands/accelerate_cli.py", line 47, in main
    args.func(args)
  File "/fsx-storygen/beidic/anaconda3/envs/griffin/lib/python3.9/site-packages/accelerate/commands/launch.py", line 985, in launch_command
    multi_gpu_launcher(args)
  File "/fsx-storygen/beidic/anaconda3/envs/griffin/lib/python3.9/site-packages/accelerate/commands/launch.py", line 654, in multi_gpu_launcher
    distrib_run.run(args)
  File "/fsx-storygen/beidic/anaconda3/envs/griffin/lib/python3.9/site-packages/torch/distributed/run.py", line 803, in run
    elastic_launch(
  File "/fsx-storygen/beidic/anaconda3/envs/griffin/lib/python3.9/site-packages/torch/distributed/launcher/api.py", line 135, in __call__
    return launch_agent(self._config, self._entrypoint, list(args))
  File "/fsx-storygen/beidic/anaconda3/envs/griffin/lib/python3.9/site-packages/torch/distributed/launcher/api.py", line 268, in launch_agent
    raise ChildFailedError(
torch.distributed.elastic.multiprocessing.errors.ChildFailedError: 
============================================================
main.py FAILED
------------------------------------------------------------
Failures:
[1]:
  time      : 2024-07-24_22:48:50
  host      : a100-st-p4de24xlarge-338.fair-a100.hpcaas
  rank      : 1 (local_rank: 1)
  exitcode  : 1 (pid: 3831143)
  error_file: <N/A>
  traceback : To enable traceback see: https://pytorch.org/docs/stable/elastic/errors.html
[2]:
  time      : 2024-07-24_22:48:50
  host      : a100-st-p4de24xlarge-338.fair-a100.hpcaas
  rank      : 2 (local_rank: 2)
  exitcode  : 1 (pid: 3831144)
  error_file: <N/A>
  traceback : To enable traceback see: https://pytorch.org/docs/stable/elastic/errors.html
[3]:
  time      : 2024-07-24_22:48:50
  host      : a100-st-p4de24xlarge-338.fair-a100.hpcaas
  rank      : 3 (local_rank: 3)
  exitcode  : 1 (pid: 3831145)
  error_file: <N/A>
  traceback : To enable traceback see: https://pytorch.org/docs/stable/elastic/errors.html
[4]:
  time      : 2024-07-24_22:48:50
  host      : a100-st-p4de24xlarge-338.fair-a100.hpcaas
  rank      : 4 (local_rank: 4)
  exitcode  : 1 (pid: 3831146)
  error_file: <N/A>
  traceback : To enable traceback see: https://pytorch.org/docs/stable/elastic/errors.html
[5]:
  time      : 2024-07-24_22:48:50
  host      : a100-st-p4de24xlarge-338.fair-a100.hpcaas
  rank      : 5 (local_rank: 5)
  exitcode  : 1 (pid: 3831147)
  error_file: <N/A>
  traceback : To enable traceback see: https://pytorch.org/docs/stable/elastic/errors.html
[6]:
  time      : 2024-07-24_22:48:50
  host      : a100-st-p4de24xlarge-338.fair-a100.hpcaas
  rank      : 6 (local_rank: 6)
  exitcode  : 1 (pid: 3831148)
  error_file: <N/A>
  traceback : To enable traceback see: https://pytorch.org/docs/stable/elastic/errors.html
[7]:
  time      : 2024-07-24_22:48:50
  host      : a100-st-p4de24xlarge-338.fair-a100.hpcaas
  rank      : 7 (local_rank: 7)
  exitcode  : 1 (pid: 3831149)
  error_file: <N/A>
  traceback : To enable traceback see: https://pytorch.org/docs/stable/elastic/errors.html
------------------------------------------------------------
Root Cause (first observed failure):
[0]:
  time      : 2024-07-24_22:48:50
  host      : a100-st-p4de24xlarge-338.fair-a100.hpcaas
  rank      : 0 (local_rank: 0)
  exitcode  : 1 (pid: 3831142)
  error_file: <N/A>
  traceback : To enable traceback see: https://pytorch.org/docs/stable/elastic/errors.html
============================================================
