Already on 'yangexp2two'
wandb: Currently logged in as: stevenzhou0816100. Use `wandb login --relogin` to force relogin
The following values were not passed to `accelerate launch` and had defaults used instead:
		More than one GPU was found, enabling multi-GPU training.
		If this was unintended please pass in `--num_processes=1`.
	`--mixed_precision` was set to a value of `'no'`
	`--dynamo_backend` was set to a value of `'no'`
To avoid this warning pass in values for each of the problematic parameters or run `accelerate config`.
2024-07-24:10:09:31,913 INFO     [main.py:288] Verbosity set to INFO
2024-07-24:10:09:31,998 INFO     [main.py:288] Verbosity set to INFO
2024-07-24:10:09:32,059 INFO     [main.py:288] Verbosity set to INFO
2024-07-24:10:09:32,072 INFO     [main.py:288] Verbosity set to INFO
2024-07-24:10:09:32,078 INFO     [main.py:288] Verbosity set to INFO
2024-07-24:10:09:32,085 INFO     [main.py:288] Verbosity set to INFO
2024-07-24:10:09:32,102 INFO     [main.py:288] Verbosity set to INFO
2024-07-24:10:09:32,108 INFO     [main.py:288] Verbosity set to INFO
2024-07-24:10:09:38,859 ERROR    [main.py:344] Tasks were not found: gsm8k-cot
                                               Try `lm-eval --tasks list` for list of available tasks
Traceback (most recent call last):
  File "/opt/hpcaas/.mounts/fs-03efe25c053395d1f/beidic/yang/GRIFFIN2/main.py", line 465, in <module>
    cli_evaluate()
  File "/opt/hpcaas/.mounts/fs-03efe25c053395d1f/beidic/yang/GRIFFIN2/main.py", line 348, in cli_evaluate
    raise ValueError(
ValueError: Tasks not found: gsm8k-cot. Try `lm-eval --tasks list` for list of available tasks, or '--verbosity DEBUG' to troubleshoot task registration issues.
2024-07-24:10:09:38,901 ERROR    [main.py:344] Tasks were not found: gsm8k-cot
                                               Try `lm-eval --tasks list` for list of available tasks
Traceback (most recent call last):
  File "/opt/hpcaas/.mounts/fs-03efe25c053395d1f/beidic/yang/GRIFFIN2/main.py", line 465, in <module>
    cli_evaluate()
  File "/opt/hpcaas/.mounts/fs-03efe25c053395d1f/beidic/yang/GRIFFIN2/main.py", line 348, in cli_evaluate
    raise ValueError(
ValueError: Tasks not found: gsm8k-cot. Try `lm-eval --tasks list` for list of available tasks, or '--verbosity DEBUG' to troubleshoot task registration issues.
2024-07-24:10:09:38,956 ERROR    [main.py:344] Tasks were not found: gsm8k-cot
                                               Try `lm-eval --tasks list` for list of available tasks
Traceback (most recent call last):
  File "/opt/hpcaas/.mounts/fs-03efe25c053395d1f/beidic/yang/GRIFFIN2/main.py", line 465, in <module>
    cli_evaluate()
  File "/opt/hpcaas/.mounts/fs-03efe25c053395d1f/beidic/yang/GRIFFIN2/main.py", line 348, in cli_evaluate
    raise ValueError(
ValueError: Tasks not found: gsm8k-cot. Try `lm-eval --tasks list` for list of available tasks, or '--verbosity DEBUG' to troubleshoot task registration issues.
2024-07-24:10:09:39,114 ERROR    [main.py:344] Tasks were not found: gsm8k-cot
                                               Try `lm-eval --tasks list` for list of available tasks
Traceback (most recent call last):
  File "/opt/hpcaas/.mounts/fs-03efe25c053395d1f/beidic/yang/GRIFFIN2/main.py", line 465, in <module>
    cli_evaluate()
  File "/opt/hpcaas/.mounts/fs-03efe25c053395d1f/beidic/yang/GRIFFIN2/main.py", line 348, in cli_evaluate
    raise ValueError(
ValueError: Tasks not found: gsm8k-cot. Try `lm-eval --tasks list` for list of available tasks, or '--verbosity DEBUG' to troubleshoot task registration issues.
2024-07-24:10:09:39,186 ERROR    [main.py:344] Tasks were not found: gsm8k-cot
                                               Try `lm-eval --tasks list` for list of available tasks
Traceback (most recent call last):
  File "/opt/hpcaas/.mounts/fs-03efe25c053395d1f/beidic/yang/GRIFFIN2/main.py", line 465, in <module>
    cli_evaluate()
  File "/opt/hpcaas/.mounts/fs-03efe25c053395d1f/beidic/yang/GRIFFIN2/main.py", line 348, in cli_evaluate
    raise ValueError(
ValueError: Tasks not found: gsm8k-cot. Try `lm-eval --tasks list` for list of available tasks, or '--verbosity DEBUG' to troubleshoot task registration issues.
2024-07-24:10:09:39,267 ERROR    [main.py:344] Tasks were not found: gsm8k-cot
                                               Try `lm-eval --tasks list` for list of available tasks
Traceback (most recent call last):
  File "/opt/hpcaas/.mounts/fs-03efe25c053395d1f/beidic/yang/GRIFFIN2/main.py", line 465, in <module>
    cli_evaluate()
  File "/opt/hpcaas/.mounts/fs-03efe25c053395d1f/beidic/yang/GRIFFIN2/main.py", line 348, in cli_evaluate
    raise ValueError(
ValueError: Tasks not found: gsm8k-cot. Try `lm-eval --tasks list` for list of available tasks, or '--verbosity DEBUG' to troubleshoot task registration issues.
2024-07-24:10:09:39,511 ERROR    [main.py:344] Tasks were not found: gsm8k-cot
                                               Try `lm-eval --tasks list` for list of available tasks
Traceback (most recent call last):
  File "/opt/hpcaas/.mounts/fs-03efe25c053395d1f/beidic/yang/GRIFFIN2/main.py", line 465, in <module>
    cli_evaluate()
  File "/opt/hpcaas/.mounts/fs-03efe25c053395d1f/beidic/yang/GRIFFIN2/main.py", line 348, in cli_evaluate
    raise ValueError(
ValueError: Tasks not found: gsm8k-cot. Try `lm-eval --tasks list` for list of available tasks, or '--verbosity DEBUG' to troubleshoot task registration issues.
[2024-07-24 10:09:39,726] torch.distributed.elastic.multiprocessing.api: [WARNING] Sending process 1672520 closing signal SIGTERM
[2024-07-24 10:09:39,726] torch.distributed.elastic.multiprocessing.api: [WARNING] Sending process 1672521 closing signal SIGTERM
[2024-07-24 10:09:39,726] torch.distributed.elastic.multiprocessing.api: [WARNING] Sending process 1672522 closing signal SIGTERM
[2024-07-24 10:09:39,727] torch.distributed.elastic.multiprocessing.api: [WARNING] Sending process 1672523 closing signal SIGTERM
[2024-07-24 10:09:39,727] torch.distributed.elastic.multiprocessing.api: [WARNING] Sending process 1672524 closing signal SIGTERM
[2024-07-24 10:09:40,537] torch.distributed.elastic.multiprocessing.api: [ERROR] failed (exitcode: 1) local_rank: 5 (pid: 1672525) of binary: /fsx-storygen/beidic/anaconda3/envs/griffin/bin/python3.9
Traceback (most recent call last):
  File "/fsx-storygen/beidic/anaconda3/envs/griffin/bin/accelerate", line 8, in <module>
    sys.exit(main())
  File "/fsx-storygen/beidic/anaconda3/envs/griffin/lib/python3.9/site-packages/accelerate/commands/accelerate_cli.py", line 47, in main
    args.func(args)
  File "/fsx-storygen/beidic/anaconda3/envs/griffin/lib/python3.9/site-packages/accelerate/commands/launch.py", line 985, in launch_command
    multi_gpu_launcher(args)
  File "/fsx-storygen/beidic/anaconda3/envs/griffin/lib/python3.9/site-packages/accelerate/commands/launch.py", line 654, in multi_gpu_launcher
    distrib_run.run(args)
  File "/fsx-storygen/beidic/anaconda3/envs/griffin/lib/python3.9/site-packages/torch/distributed/run.py", line 803, in run
    elastic_launch(
  File "/fsx-storygen/beidic/anaconda3/envs/griffin/lib/python3.9/site-packages/torch/distributed/launcher/api.py", line 135, in __call__
    return launch_agent(self._config, self._entrypoint, list(args))
  File "/fsx-storygen/beidic/anaconda3/envs/griffin/lib/python3.9/site-packages/torch/distributed/launcher/api.py", line 268, in launch_agent
    raise ChildFailedError(
torch.distributed.elastic.multiprocessing.errors.ChildFailedError: 
============================================================
main.py FAILED
------------------------------------------------------------
Failures:
[1]:
  time      : 2024-07-24_10:09:39
  host      : a100-st-p4de24xlarge-118.fair-a100.hpcaas
  rank      : 6 (local_rank: 6)
  exitcode  : 1 (pid: 1672526)
  error_file: <N/A>
  traceback : To enable traceback see: https://pytorch.org/docs/stable/elastic/errors.html
[2]:
  time      : 2024-07-24_10:09:39
  host      : a100-st-p4de24xlarge-118.fair-a100.hpcaas
  rank      : 7 (local_rank: 7)
  exitcode  : 1 (pid: 1672527)
  error_file: <N/A>
  traceback : To enable traceback see: https://pytorch.org/docs/stable/elastic/errors.html
------------------------------------------------------------
Root Cause (first observed failure):
[0]:
  time      : 2024-07-24_10:09:39
  host      : a100-st-p4de24xlarge-118.fair-a100.hpcaas
  rank      : 5 (local_rank: 5)
  exitcode  : 1 (pid: 1672525)
  error_file: <N/A>
  traceback : To enable traceback see: https://pytorch.org/docs/stable/elastic/errors.html
============================================================
